Workbook

Sheet Scores
B1: Code Golf International | C1: rucin93 | D1: ox jam | E1: open source | F1: jailctf merger | G1: Rafael Pooja | H1: HETHAT | I1: duckyluuk | J1: import itertools | K1: ALE-Agent | L1: JRKKX | M1: intgrah jimboko awu macaque sammyuri | N1: mji | O1: cefqrn | P1: hyacinth | Q1: cg | R1: Team JYCDT | S1: Bulmenisaurus | T1: dbdr | U1: KN | V1: kabutack | W1: biz | X1: scpchicken | Y1: el_presidente | Z1: ﾀｲｽｹﾝｻﾝﾊﾞII | AA1: garrymoss | AB1: azakhtyamov | AC1: Ali | AD1: blob2822 | AE1: kdmitrie | AF1: MKRC | AG1: Afordancja | AH1: Yuchen20 | AI1: cg-klogw-sekken | AJ1: sekken | AK1: cubbus | AL1: Ty Woods | AM1: Ravi Annaswamy | AN1: today | AO1: LogicLynx | AP1: kambarakun | AQ1: ShadowPrompt Labs | AS1: THUNDER THUNDER | AT1: Krige | AU1: HIMAGINE THE FUTURE. | AV1: FuunAgent | AW1: lv1.dev | AX1: santa2024 | AY1: The Ultimate Golfer
A2: SCORE | B2: {=LET( result, SUM(IF(ISNUMBER(B12:B411), IF((2500 - B12:B411) > 1, 2500 - B12:B411, 1), 0)), IF(result = 0, "", result) )} -> 962070 | C2: {=LET( result, SUM(IF(ISNUMBER(C12:C411), IF((2500 - C12:C411) > 1, 2500 - C12:C411, 1), 0)), IF(result = 0, "", result) )} -> 913684 | D2: {=LET( result, SUM(IF(ISNUMBER(D12:D411), IF((2500 - D12:D411) > 1, 2500 - D12:D411, 1), 0)), IF(result = 0, "", result) )} -> 961784 | E2: {=LET( result, SUM(IF(ISNUMBER(E12:E411), IF((2500 - E12:E411) > 1, 2500 - E12:E411, 1), 0)), IF(result = 0, "", result) )} -> 913549 | F2: {=LET( result, SUM(IF(ISNUMBER(F12:F411), IF((2500 - F12:F411) > 1, 2500 - F12:F411, 1), 0)), IF(result = 0, "", result) )} -> 961805 | G2: {=LET( result, SUM(IF(ISNUMBER(G12:G411), IF((2500 - G12:G411) > 1, 2500 - G12:G411, 1), 0)), IF(result = 0, "", result) )} -> 906884 | H2: {=LET( result, SUM(IF(ISNUMBER(H12:H411), IF((2500 - H12:H411) > 1, 2500 - H12:H411, 1), 0)), IF(result = 0, "", result) )} -> 370321 | I2: {=LET( result, SUM(IF(ISNUMBER(I12:I411), IF((2500 - I12:I411) > 1, 2500 - I12:I411, 1), 0)), IF(result = 0, "", result) )} -> 431944 | ... AQ2: {=LET( result, SUM(IF(ISNUMBER(AQ12:AQ411), IF((2500 - AQ12:AQ411) > 1, 2500 - AQ12:AQ411, 1), 0)), IF(result = 0, "", result) )} -> 944204 | AR2: {=LET( result, SUM(IF(ISNUMBER(AR13:AR411), IF((2500 - AR13:AR411) > 1, 2500 - AR13:AR411, 1), 0)), IF(result = 0, "", result) )} | AS2: {=LET( result, SUM(IF(ISNUMBER(AS12:AS411), IF((2500 - AS12:AS411) > 1, 2500 - AS12:AS411, 1), 0)), IF(result = 0, "", result) )} -> 951260 | AT2: {=LET( result, SUM(IF(ISNUMBER(AT12:AT411), IF((2500 - AT12:AT411) > 1, 2500 - AT12:AT411, 1), 0)), IF(result = 0, "", result) )} -> 925835 | AU2: {=LET( result, SUM(IF(ISNUMBER(AU12:AU411), IF((2500 - AU12:AU411) > 1, 2500 - AU12:AU411, 1), 0)), IF(result = 0, "", result) )} -> 957568 | AV2: {=LET( result, SUM(IF(ISNUMBER(AV12:AV411), IF((2500 - AV12:AV411) > 1, 2500 - AV12:AV411, 1), 0)), IF(result = 0, "", result) )} -> 957810 | AW2: {=LET( result, SUM(IF(ISNUMBER(AW12:AW411), IF((2500 - AW12:AW411) > 1, 2500 - AW12:AW411, 1), 0)), IF(result = 0, "", result) )} -> 956458 | AX2: {=LET( result, SUM(IF(ISNUMBER(AX12:AX411), IF((2500 - AX12:AX411) > 1, 2500 - AX12:AX411, 1), 0)), IF(result = 0, "", result) )} -> 954246 | AY2: {=LET( result, SUM(IF(ISNUMBER(AY12:AY411), IF((2500 - AY12:AY411) > 1, 2500 - AY12:AY411, 1), 0)), IF(result = 0, "", result) )} -> 963477 | AZ2: {=LET( result, SUM(IF(ISNUMBER(AZ12:AZ411), IF((2500 - AZ12:AZ411) > 1, 2500 - AZ12:AZ411, 1), 0)), IF(result = 0, "", result) )} | ... BC2: {=LET( result, SUM(IF(ISNUMBER(BC12:BC411), IF((2500 - BC12:BC411) > 1, 2500 - BC12:BC411, 1), 0)), IF(result = 0, "", result) )}
A3: MEDALS | B3: =IF(COUNT(B12:B411)=0, "", concatenate("💎",sumproduct(B12:B411=Compilation!$E9:$E408)," 🥇",sumproduct(B12:B411=Compilation!$F9:$F408)," 🥈",sumproduct(B12:B411=Compilation!$G9:$G408)," 🥉",sumproduct(B12:B411=Compilation!$H9:$H408))) -> 💎83 🥇231 🥈82 🥉52 | C3: =IF(COUNT(C12:C411)=0, "", concatenate("💎",sumproduct(C12:C411=Compilation!$E9:$E408)," 🥇",sumproduct(C12:C411=Compilation!$F9:$F408)," 🥈",sumproduct(C12:C411=Compilation!$G9:$G408)," 🥉",sumproduct(C12:C411=Compilation!$H9:$H408))) -> 💎0 🥇18 🥈0 🥉0 | D3: =IF(COUNT(D12:D411)=0, "", concatenate("💎",sumproduct(D12:D411=Compilation!$E9:$E408)," 🥇",sumproduct(D12:D411=Compilation!$F9:$F408)," 🥈",sumproduct(D12:D411=Compilation!$G9:$G408)," 🥉",sumproduct(D12:D411=Compilation!$H9:$H408))) -> 💎71 🥇197 🥈83 🥉52 | E3: =IF(COUNT(E12:E411)=0, "", concatenate("💎",sumproduct(E12:E411=Compilation!$E9:$E408)," 🥇",sumproduct(E12:E411=Compilation!$F9:$F408)," 🥈",sumproduct(E12:E411=Compilation!$G9:$G408)," 🥉",sumproduct(E12:E411=Compilation!$H9:$H408))) -> 💎0 🥇18 🥈0 🥉0 | F3: =IF(COUNT(F12:F411)=0, "", concatenate("💎",sumproduct(F12:F411=Compilation!$E9:$E408)," 🥇",sumproduct(F12:F411=Compilation!$F9:$F408)," 🥈",sumproduct(F12:F411=Compilation!$G9:$G408)," 🥉",sumproduct(F12:F411=Compilation!$H9:$H408))) -> 💎55 🥇193 🥈99 🥉67 | G3: =IF(COUNT(G12:G411)=0, "", concatenate("💎",sumproduct(G12:G411=Compilation!$E9:$E408)," 🥇",sumproduct(G12:G411=Compilation!$F9:$F408)," 🥈",sumproduct(G12:G411=Compilation!$G9:$G408)," 🥉",sumproduct(G12:G411=Compilation!$H9:$H408))) -> 💎0 🥇27 🥈3 🥉0 | H3: =IF(COUNT(H12:H411)=0, "", concatenate("💎",sumproduct(H12:H411=Compilation!$E9:$E408)," 🥇",sumproduct(H12:H411=Compilation!$F9:$F408)," 🥈",sumproduct(H12:H411=Compilation!$G9:$G408)," 🥉",sumproduct(H12:H411=Compilation!$H9:$H408))) -> 💎0 🥇37 🥈4 🥉1 | I3: =IF(COUNT(I12:I411)=0, "", concatenate("💎",sumproduct(I12:I411=Compilation!$E9:$E408)," 🥇",sumproduct(I12:I411=Compilation!$F9:$F408)," 🥈",sumproduct(I12:I411=Compilation!$G9:$G408)," 🥉",sumproduct(I12:I411=Compilation!$H9:$H408))) -> 💎0 🥇24 🥈5 🥉0 | ... AQ3: =IF(COUNT(AQ12:AQ411)=0, "", concatenate("💎",sumproduct(AQ12:AQ411=Compilation!$E9:$E408)," 🥇",sumproduct(AQ12:AQ411=Compilation!$F9:$F408)," 🥈",sumproduct(AQ12:AQ411=Compilation!$G9:$G408)," 🥉",sumproduct(AQ12:AQ411=Compilation!$H9:$H408))) -> 💎0 🥇36 🥈4 🥉0 | AR3: =IF(COUNT(AR13:AR411)=0, "", concatenate("💎",sumproduct(AR13:AR411=Compilation!$E9:$E408)," 🥇",sumproduct(AR13:AR411=Compilation!$F9:$F408)," 🥈",sumproduct(AR13:AR411=Compilation!$G9:$G408)," 🥉",sumproduct(AR13:AR411=Compilation!$H9:$H408))) | AS3: =IF(COUNT(AS12:AS411)=0, "", concatenate("💎",sumproduct(AS12:AS411=Compilation!$E9:$E408)," 🥇",sumproduct(AS12:AS411=Compilation!$F9:$F408)," 🥈",sumproduct(AS12:AS411=Compilation!$G9:$G408)," 🥉",sumproduct(AS12:AS411=Compilation!$H9:$H408))) -> 💎0 🥇34 🥈5 🥉0 | AT3: =IF(COUNT(AT12:AT411)=0, "", concatenate("💎",sumproduct(AT12:AT411=Compilation!$E9:$E408)," 🥇",sumproduct(AT12:AT411=Compilation!$F9:$F408)," 🥈",sumproduct(AT12:AT411=Compilation!$G9:$G408)," 🥉",sumproduct(AT12:AT411=Compilation!$H9:$H408))) -> 💎0 🥇18 🥈0 🥉0 | AU3: =IF(COUNT(AU12:AU411)=0, "", concatenate("💎",sumproduct(AU12:AU411=Compilation!$E9:$E408)," 🥇",sumproduct(AU12:AU411=Compilation!$F9:$F408)," 🥈",sumproduct(AU12:AU411=Compilation!$G9:$G408)," 🥉",sumproduct(AU12:AU411=Compilation!$H9:$H408))) -> 💎0 🥇58 🥈15 🥉10 | AV3: =IF(COUNT(AV12:AV411)=0, "", concatenate("💎",sumproduct(AV12:AV411=Compilation!$E9:$E408)," 🥇",sumproduct(AV12:AV411=Compilation!$F9:$F408)," 🥈",sumproduct(AV12:AV411=Compilation!$G9:$G408)," 🥉",sumproduct(AV12:AV411=Compilation!$H9:$H408))) -> 💎3 🥇76 🥈23 🥉13 | AW3: =IF(COUNT(AW12:AW411)=0, "", concatenate("💎",sumproduct(AW12:AW411=Compilation!$E9:$E408)," 🥇",sumproduct(AW12:AW411=Compilation!$F9:$F408)," 🥈",sumproduct(AW12:AW411=Compilation!$G9:$G408)," 🥉",sumproduct(AW12:AW411=Compilation!$H9:$H408))) -> 💎3 🥇96 🥈26 🥉13 | AX3: =IF(COUNT(AX12:AX411)=0, "", concatenate("💎",sumproduct(AX12:AX411=Compilation!$E9:$E408)," 🥇",sumproduct(AX12:AX411=Compilation!$F9:$F408)," 🥈",sumproduct(AX12:AX411=Compilation!$G9:$G408)," 🥉",sumproduct(AX12:AX411=Compilation!$H9:$H408))) -> 💎0 🥇53 🥈9 🥉5 | AY3: =IF(COUNT(AY12:AY411)=0, "", concatenate("💎",sumproduct(AY12:AY411=Compilation!$E9:$E408)," 🥇",sumproduct(AY12:AY411=Compilation!$F9:$F408)," 🥈",sumproduct(AY12:AY411=Compilation!$G9:$G408)," 🥉",sumproduct(AY12:AY411=Compilation!$H9:$H408))) -> 💎186 🥇340 🥈0 🥉0 | AZ3: =IF(COUNT(AZ12:AZ411)=0, "", concatenate("💎",sumproduct(AZ12:AZ411=Compilation!$E9:$E408)," 🥇",sumproduct(AZ12:AZ411=Compilation!$F9:$F408)," 🥈",sumproduct(AZ12:AZ411=Compilation!$G9:$G408)," 🥉",sumproduct(AZ12:AZ411=Compilation!$H9:$H408))) | ... BC3: =IF(COUNT(BC12:BC411)=0, "", concatenate("💎",sumproduct(BC12:BC411=Compilation!$E9:$E408)," 🥇",sumproduct(BC12:BC411=Compilation!$F9:$F408)," 🥈",sumproduct(BC12:BC411=Compilation!$G9:$G408)," 🥉",sumproduct(BC12:BC411=Compilation!$H9:$H408)))
A4: COUNT | B4: =LET( result, COUNT(B12:B411), IF(result = 0, "", result) ) -> 400 | C4: =LET( result, COUNT(C12:C411), IF(result = 0, "", result) ) -> 400 | D4: =LET( result, COUNT(D12:D411), IF(result = 0, "", result) ) -> 400 | E4: =LET( result, COUNT(E12:E411), IF(result = 0, "", result) ) -> 400 | F4: =LET( result, COUNT(F12:F411), IF(result = 0, "", result) ) -> 400 | G4: =LET( result, COUNT(G12:G411), IF(result = 0, "", result) ) -> 400 | H4: =LET( result, COUNT(H12:H411), IF(result = 0, "", result) ) -> 152 | I4: =LET( result, COUNT(I12:I411), IF(result = 0, "", result) ) -> 180 | ... AQ4: =LET( result, COUNT(AQ12:AQ411), IF(result = 0, "", result) ) -> 400 | AR4: =LET( result, COUNT(AR13:AR411), IF(result = 0, "", result) ) | AS4: =LET( result, COUNT(AS12:AS411), IF(result = 0, "", result) ) -> 400 | AT4: =LET( result, COUNT(AT12:AT411), IF(result = 0, "", result) ) -> 400 | AU4: =LET( result, COUNT(AU12:AU411), IF(result = 0, "", result) ) -> 400 | AV4: =LET( result, COUNT(AV12:AV411), IF(result = 0, "", result) ) -> 400 | AW4: =LET( result, COUNT(AW12:AW411), IF(result = 0, "", result) ) -> 400 | AX4: =LET( result, COUNT(AX12:AX411), IF(result = 0, "", result) ) -> 400 | AY4: =LET( result, COUNT(AY12:AY411), IF(result = 0, "", result) ) -> 400 | AZ4: =LET( result, COUNT(AZ12:AZ411), IF(result = 0, "", result) ) | ... BC4: =LET( result, COUNT(BC12:BC411), IF(result = 0, "", result) )
A5: SUM | B5: =LET( result, SUM(B12:B411), IF(result = 0, "", result) ) -> 37930 | C5: =LET( result, SUM(C12:C411), IF(result = 0, "", result) ) -> 86316 | D5: =LET( result, SUM(D12:D411), IF(result = 0, "", result) ) -> 38216 | E5: =LET( result, SUM(E12:E411), IF(result = 0, "", result) ) -> 86451 | F5: =LET( result, SUM(F12:F411), IF(result = 0, "", result) ) -> 38195 | G5: =LET( result, SUM(G12:G411), IF(result = 0, "", result) ) -> 93116 | H5: =LET( result, SUM(H12:H411), IF(result = 0, "", result) ) -> 9679 | I5: =LET( result, SUM(I12:I411), IF(result = 0, "", result) ) -> 18056 | ... AQ5: =LET( result, SUM(AQ12:AQ411), IF(result = 0, "", result) ) -> 55796 | AR5: =LET( result, SUM(AR13:AR411), IF(result = 0, "", result) ) | AS5: =LET( result, SUM(AS12:AS411), IF(result = 0, "", result) ) -> 48740 | AT5: =LET( result, SUM(AT12:AT411), IF(result = 0, "", result) ) -> 74165 | AU5: =LET( result, SUM(AU12:AU411), IF(result = 0, "", result) ) -> 42432 | AV5: =LET( result, SUM(AV12:AV411), IF(result = 0, "", result) ) -> 42190 | AW5: =LET( result, SUM(AW12:AW411), IF(result = 0, "", result) ) -> 43542 | AX5: =LET( result, SUM(AX12:AX411), IF(result = 0, "", result) ) -> 45754 | AY5: =LET( result, SUM(AY12:AY411), IF(result = 0, "", result) ) -> 36523 | AZ5: =LET( result, SUM(AZ12:AZ411), IF(result = 0, "", result) ) | ... BC5: =LET( result, SUM(BC12:BC411), IF(result = 0, "", result) )
A6: AVG | B6: =IFERROR(AVERAGE(B12:B411), "") -> 94.825 | C6: =IFERROR(AVERAGE(C12:C411), "") -> 215.79 | D6: =IFERROR(AVERAGE(D12:D411), "") -> 95.54 | E6: =IFERROR(AVERAGE(E12:E411), "") -> 216.1275 | F6: =IFERROR(AVERAGE(F12:F411), "") -> 95.4875 | G6: =IFERROR(AVERAGE(G12:G411), "") -> 232.79 | H6: =IFERROR(AVERAGE(H12:H411), "") -> 63.677632 | I6: =IFERROR(AVERAGE(I12:I411), "") -> 100.31111 | ... AQ6: =IFERROR(AVERAGE(AQ12:AQ411), "") -> 139.49 | AR6: =IFERROR(AVERAGE(AR13:AR411), "") | AS6: =IFERROR(AVERAGE(AS12:AS411), "") -> 121.85 | AT6: =IFERROR(AVERAGE(AT12:AT411), "") -> 185.4125 | AU6: =IFERROR(AVERAGE(AU12:AU411), "") -> 106.08 | AV6: =IFERROR(AVERAGE(AV12:AV411), "") -> 105.475 | AW6: =IFERROR(AVERAGE(AW12:AW411), "") -> 108.855 | AX6: =IFERROR(AVERAGE(AX12:AX411), "") -> 114.385 | AY6: =IFERROR(AVERAGE(AY12:AY411), "") -> 91.3075 | AZ6: =IFERROR(AVERAGE(AZ12:AZ411), "") | ... BC6: =IFERROR(AVERAGE(BC12:BC411), "")
A7: ΔSUM | B7: {=IF(COUNT(B12:B411)=0, "", SUM(IF(ISNUMBER(B12:B411), B12:B411 - Compilation!$F9:$F408)))} -> 1127 | C7: {=IF(COUNT(C12:C411)=0, "", SUM(IF(ISNUMBER(C12:C411), C12:C411 - Compilation!$F9:$F408)))} -> 49513 | D7: {=IF(COUNT(D12:D411)=0, "", SUM(IF(ISNUMBER(D12:D411), D12:D411 - Compilation!$F9:$F408)))} -> 1413 | E7: {=IF(COUNT(E12:E411)=0, "", SUM(IF(ISNUMBER(E12:E411), E12:E411 - Compilation!$F9:$F408)))} -> 49648 | F7: {=IF(COUNT(F12:F411)=0, "", SUM(IF(ISNUMBER(F12:F411), F12:F411 - Compilation!$F9:$F408)))} -> 1392 | G7: {=IF(COUNT(G12:G411)=0, "", SUM(IF(ISNUMBER(G12:G411), G12:G411 - Compilation!$F9:$F408)))} -> 56313 | H7: {=IF(COUNT(H12:H411)=0, "", SUM(IF(ISNUMBER(H12:H411), H12:H411 - Compilation!$F9:$F408)))} -> 1477 | I7: {=IF(COUNT(I12:I411)=0, "", SUM(IF(ISNUMBER(I12:I411), I12:I411 - Compilation!$F9:$F408)))} -> 5490 | ... AQ7: {=IF(COUNT(AQ12:AQ411)=0, "", SUM(IF(ISNUMBER(AQ12:AQ411), AQ12:AQ411 - Compilation!$F9:$F408)))} -> 18993 | AR7: {=IF(COUNT(AR13:AR411)=0, "", SUM(IF(ISNUMBER(AR13:AR411), AR13:AR411 - Compilation!$F9:$F408)))} | AS7: {=IF(COUNT(AS12:AS411)=0, "", SUM(IF(ISNUMBER(AS12:AS411), AS12:AS411 - Compilation!$F9:$F408)))} -> 11937 | AT7: {=IF(COUNT(AT12:AT411)=0, "", SUM(IF(ISNUMBER(AT12:AT411), AT12:AT411 - Compilation!$F9:$F408)))} -> 37362 | AU7: {=IF(COUNT(AU12:AU411)=0, "", SUM(IF(ISNUMBER(AU12:AU411), AU12:AU411 - Compilation!$F9:$F408)))} -> 5629 | AV7: {=IF(COUNT(AV12:AV411)=0, "", SUM(IF(ISNUMBER(AV12:AV411), AV12:AV411 - Compilation!$F9:$F408)))} -> 5387 | AW7: {=IF(COUNT(AW12:AW411)=0, "", SUM(IF(ISNUMBER(AW12:AW411), AW12:AW411 - Compilation!$F9:$F408)))} -> 6739 | AX7: {=IF(COUNT(AX12:AX411)=0, "", SUM(IF(ISNUMBER(AX12:AX411), AX12:AX411 - Compilation!$F9:$F408)))} -> 8951 | AY7: {=IF(COUNT(AY12:AY411)=0, "", SUM(IF(ISNUMBER(AY12:AY411), AY12:AY411 - Compilation!$F9:$F408)))} -> -280 | AZ7: {=IF(COUNT(AZ12:AZ411)=0, "", SUM(IF(ISNUMBER(AZ12:AZ411), AZ12:AZ411 - Compilation!$F9:$F408)))} | ... BC7: {=IF(COUNT(BC12:BC411)=0, "", SUM(IF(ISNUMBER(BC12:BC411), BC12:BC411 - Compilation!$F9:$F408)))}
A8: ΔAVG | B8: {=IF(COUNT(B12:B411)=0, "", AVERAGE(IF(ISNUMBER(B12:B411), B12:B411 - Compilation!$F9:$F408)))} -> 2.8175 | C8: {=IF(COUNT(C12:C411)=0, "", AVERAGE(IF(ISNUMBER(C12:C411), C12:C411 - Compilation!$F9:$F408)))} -> 123.7825 | D8: {=IF(COUNT(D12:D411)=0, "", AVERAGE(IF(ISNUMBER(D12:D411), D12:D411 - Compilation!$F9:$F408)))} -> 3.5325 | E8: {=IF(COUNT(E12:E411)=0, "", AVERAGE(IF(ISNUMBER(E12:E411), E12:E411 - Compilation!$F9:$F408)))} -> 124.12 | F8: {=IF(COUNT(F12:F411)=0, "", AVERAGE(IF(ISNUMBER(F12:F411), F12:F411 - Compilation!$F9:$F408)))} -> 3.48 | G8: {=IF(COUNT(G12:G411)=0, "", AVERAGE(IF(ISNUMBER(G12:G411), G12:G411 - Compilation!$F9:$F408)))} -> 140.7825 | H8: {=IF(COUNT(H12:H411)=0, "", AVERAGE(IF(ISNUMBER(H12:H411), H12:H411 - Compilation!$F9:$F408)))} -> 9.7171053 | I8: {=IF(COUNT(I12:I411)=0, "", AVERAGE(IF(ISNUMBER(I12:I411), I12:I411 - Compilation!$F9:$F408)))} -> 30.5 | ... AQ8: {=IF(COUNT(AQ12:AQ411)=0, "", AVERAGE(IF(ISNUMBER(AQ12:AQ411), AQ12:AQ411 - Compilation!$F9:$F408)))} -> 47.4825 | AR8: {=IF(COUNT(AR13:AR411)=0, "", AVERAGE(IF(ISNUMBER(AR13:AR411), AR13:AR411 - Compilation!$F9:$F408)))} | AS8: {=IF(COUNT(AS12:AS411)=0, "", AVERAGE(IF(ISNUMBER(AS12:AS411), AS12:AS411 - Compilation!$F9:$F408)))} -> 29.8425 | AT8: {=IF(COUNT(AT12:AT411)=0, "", AVERAGE(IF(ISNUMBER(AT12:AT411), AT12:AT411 - Compilation!$F9:$F408)))} -> 93.405 | AU8: {=IF(COUNT(AU12:AU411)=0, "", AVERAGE(IF(ISNUMBER(AU12:AU411), AU12:AU411 - Compilation!$F9:$F408)))} -> 14.0725 | AV8: {=IF(COUNT(AV12:AV411)=0, "", AVERAGE(IF(ISNUMBER(AV12:AV411), AV12:AV411 - Compilation!$F9:$F408)))} -> 13.4675 | AW8: {=IF(COUNT(AW12:AW411)=0, "", AVERAGE(IF(ISNUMBER(AW12:AW411), AW12:AW411 - Compilation!$F9:$F408)))} -> 16.8475 | AX8: {=IF(COUNT(AX12:AX411)=0, "", AVERAGE(IF(ISNUMBER(AX12:AX411), AX12:AX411 - Compilation!$F9:$F408)))} -> 22.3775 | AY8: {=IF(COUNT(AY12:AY411)=0, "", AVERAGE(IF(ISNUMBER(AY12:AY411), AY12:AY411 - Compilation!$F9:$F408)))} -> -0.7 | AZ8: {=IF(COUNT(AZ12:AZ411)=0, "", AVERAGE(IF(ISNUMBER(AZ12:AZ411), AZ12:AZ411 - Compilation!$F9:$F408)))} | ... BC8: {=IF(COUNT(BC12:BC411)=0, "", AVERAGE(IF(ISNUMBER(BC12:BC411), BC12:BC411 - Compilation!$F9:$F408)))}
A11: TASK
A12: =HYPERLINK("https://arcprize.org/play?task=007bbfb7", 1) -> 1 | B12: 58 | C12: 61 | D12: 58 | E12: 61 | F12: 60 | G12: 61 | H12: 61 | I12: 61 | J12: 58 | K12: 61 | L12: 61 | M12: 60 | N12: 61 | O12: 77 | P12: 105 | Q12: 61 | R12: 61 | S12: 74 | T12: 71 | U12: 71 | V12: 61 | W12: 61 | X12: 74 | Y12: 74 | Z12: 61 | AB12: 74 | AC12: 61 | AD12: 61 | AE12: 61 | AF12: 61 | AG12: 74 | AH12: 61 | AI12: 61 | AJ12: 61 | AK12: 61 | AL12: 61 | AM12: 61 | AN12: 61 | AO12: 61 | AP12: 61 | AQ12: 61 | AS12: 61 | AT12: 61 | AU12: 61 | AV12: 61 | AW12: 61 | AX12: 61 | AY12: 58
A13: =HYPERLINK("https://arcprize.org/play?task=00d62c1b", 2) -> 2 | B13: 88 | C13: 200 | D13: 88 | E13: 196 | F13: 86 | G13: 108 | H13: 96 | I13: 217 | J13: 99 | K13: 97 | L13: 102 | M13: 91 | O13: 171 | Q13: 201 | R13: 102 | T13: 338 | U13: 300 | V13: 102 | W13: 92 | X13: 259 | Y13: 259 | Z13: 101 | AB13: 200 | AC13: 196 | AD13: 110 | AE13: 188 | AF13: 202 | AG13: 314 | AH13: 200 | AI13: 129 | AJ13: 199 | AK13: 97 | AL13: 192 | AM13: 126 | AN13: 196 | AO13: 94 | AP13: 194 | AQ13: 107 | AS13: 99 | AT13: 196 | AU13: 107 | AV13: 98 | AW13: 95 | AX13: 101 | AY13: 85
A14: =HYPERLINK("https://arcprize.org/play?task=017c7c7b", 3) -> 3 | B14: 58 | C14: 65 | D14: 58 | E14: 65 | F14: 58 | G14: 65 | H14: 61 | I14: 65 | J14: 58 | K14: 58 | L14: 58 | M14: 58 | O14: 63 | Q14: 65 | R14: 61 | S14: 86 | T14: 65 | U14: 61 | V14: 61 | W14: 62 | X14: 66 | Y14: 66 | Z14: 61 | AB14: 66 | AC14: 61 | AD14: 61 | AE14: 58 | AF14: 61 | AG14: 66 | AH14: 61 | AI14: 65 | AJ14: 65 | AK14: 61 | AL14: 65 | AM14: 65 | AN14: 65 | AO14: 61 | AP14: 61 | AQ14: 61 | AS14: 65 | AT14: 65 | AU14: 61 | AV14: 58 | AW14: 58 | AX14: 58 | AY14: 58
A15: =HYPERLINK("https://arcprize.org/play?task=025d127b", 4) -> 4 | B15: 79 | C15: 194 | D15: 73 | E15: 192 | F15: 74 | G15: 194 | I15: 139 | J15: 91 | K15: 101 | L15: 110 | M15: 99 | Q15: 195 | R15: 108 | T15: 258 | U15: 222 | V15: 119 | W15: 93 | X15: 222 | Y15: 222 | Z15: 99 | AB15: 194 | AC15: 191 | AD15: 190 | AE15: 194 | AF15: 191 | AG15: 222 | AH15: 125 | AI15: 170 | AJ15: 180 | AL15: 191 | AM15: 119 | AN15: 194 | AO15: 80 | AP15: 132 | AQ15: 139 | AS15: 149 | AT15: 194 | AU15: 84 | AV15: 86 | AW15: 104 | AX15: 103 | AY15: 73
A16: =HYPERLINK("https://arcprize.org/play?task=045e512c", 5) -> 5 | B16: 174 | C16: 409 | D16: 199 | E16: 396 | F16: 166 | G16: 399 | I16: 346 | J16: 253 | K16: 235 | L16: 279 | M16: 257 | Q16: 382 | R16: 246 | W16: 279 | Y16: 437 | Z16: 242 | AB16: 400 | AC16: 424 | AD16: 438 | AE16: 279 | AF16: 494 | AG16: 484 | AH16: 358 | AI16: 273 | AJ16: 349 | AL16: 309 | AM16: 275 | AN16: 414 | AO16: 246 | AP16: 388 | AQ16: 250 | AS16: 242 | AT16: 330 | AU16: 234 | AV16: 234 | AW16: 221 | AX16: 236 | AY16: 166
A17: =HYPERLINK("https://arcprize.org/play?task=0520fde7", 6) -> 6 | B17: 49 | C17: 53 | D17: 51 | E17: 57 | F17: 49 | G17: 53 | H17: 53 | I17: 53 | J17: 51 | K17: 51 | L17: 53 | M17: 51 | N17: 53 | O17: 53 | P17: 70 | Q17: 53 | R17: 53 | T17: 57 | U17: 70 | V17: 53 | W17: 53 | X17: 71 | Y17: 71 | Z17: 51 | AB17: 71 | AC17: 57 | AD17: 53 | AE17: 53 | AF17: 57 | AG17: 59 | AH17: 53 | AI17: 53 | AJ17: 53 | AK17: 53 | AL17: 53 | AM17: 54 | AN17: 57 | AO17: 51 | AP17: 53 | AQ17: 51 | AS17: 53 | AT17: 57 | AU17: 49 | AV17: 51 | AW17: 49 | AX17: 51 | AY17: 49
A18: =HYPERLINK("https://arcprize.org/play?task=05269061", 7) -> 7 | B18: 62 | C18: 142 | D18: 63 | E18: 104 | F18: 62 | G18: 98 | H18: 72 | I18: 84 | J18: 64 | K18: 68 | L18: 72 | M18: 63 | Q18: 72 | R18: 64 | S18: 84 | T18: 180 | U18: 124 | V18: 72 | W18: 67 | X18: 155 | Y18: 155 | Z18: 72 | AB18: 155 | AC18: 126 | AD18: 104 | AE18: 72 | AF18: 118 | AG18: 108 | AH18: 72 | AI18: 72 | AJ18: 97 | AL18: 135 | AM18: 72 | AN18: 142 | AO18: 64 | AP18: 98 | AQ18: 74 | AS18: 103 | AT18: 142 | AU18: 64 | AV18: 64 | AW18: 64 | AX18: 64 | AY18: 62
A19: =HYPERLINK("https://arcprize.org/play?task=05f2a901", 8) -> 8 | B19: 84 | C19: 184 | D19: 90 | E19: 184 | F19: 84 | G19: 299 | I19: 152 | J19: 99 | K19: 97 | L19: 120 | M19: 127 | Q19: 218 | R19: 115 | U19: 394 | W19: 103 | X19: 320 | Y19: 323 | Z19: 104 | AB19: 277 | AC19: 296 | AD19: 290 | AE19: 296 | AF19: 238 | AG19: 222 | AH19: 221 | AI19: 122 | AJ19: 236 | AL19: 186 | AM19: 142 | AN19: 189 | AO19: 101 | AP19: 184 | AQ19: 146 | AS19: 149 | AT19: 186 | AU19: 99 | AV19: 125 | AW19: 114 | AX19: 99 | AY19: 83
A20: =HYPERLINK("https://arcprize.org/play?task=06df4c85", 9) -> 9 | B20: 95 | C20: 281 | D20: 109 | E20: 263 | F20: 108 | G20: 229 | H20: 126 | I20: 147 | J20: 116 | K20: 112 | L20: 123 | M20: 107 | Q20: 223 | R20: 121 | U20: 507 | V20: 123 | W20: 109 | X20: 317 | Y20: 323 | Z20: 109 | AB20: 279 | AC20: 263 | AE20: 167 | AF20: 279 | AG20: 305 | AH20: 158 | AI20: 118 | AJ20: 166 | AL20: 207 | AM20: 216 | AN20: 263 | AO20: 108 | AP20: 226 | AQ20: 240 | AS20: 119 | AT20: 263 | AU20: 116 | AV20: 113 | AW20: 112 | AX20: 113 | AY20: 95
A21: =HYPERLINK("https://arcprize.org/play?task=08ed6ac7", 10) -> 10 | B21: 66 | C21: 94 | D21: 67 | E21: 94 | F21: 67 | G21: 95 | H21: 77 | I21: 94 | J21: 68 | K21: 80 | L21: 87 | M21: 77 | Q21: 92 | R21: 83 | S21: 108 | T21: 106 | U21: 106 | V21: 88 | W21: 101 | X21: 106 | Y21: 106 | Z21: 82 | AB21: 106 | AC21: 95 | AD21: 94 | AE21: 95 | AF21: 94 | AG21: 106 | AH21: 87 | AI21: 89 | AJ21: 89 | AK21: 72 | AL21: 94 | AM21: 72 | AN21: 95 | AO21: 70 | AP21: 94 | AQ21: 87 | AS21: 83 | AT21: 94 | AU21: 71 | AV21: 71 | AW21: 71 | AX21: 82 | AY21: 66
A22: =HYPERLINK("https://arcprize.org/play?task=09629e4f", 11) -> 11 | B22: 120 | C22: 201 | D22: 114 | E22: 189 | F22: 121 | G22: 204 | H22: 155 | I22: 155 | J22: 127 | K22: 122 | L22: 133 | M22: 133 | Q22: 206 | R22: 158 | S22: 184 | U22: 309 | W22: 158 | X22: 246 | Y22: 212 | Z22: 129 | AB22: 241 | AC22: 189 | AD22: 177 | AE22: 189 | AF22: 167 | AG22: 235 | AH22: 158 | AI22: 156 | AJ22: 156 | AL22: 189 | AM22: 131 | AN22: 189 | AO22: 137 | AP22: 173 | AQ22: 153 | AS22: 166 | AT22: 189 | AU22: 140 | AV22: 141 | AW22: 141 | AX22: 145 | AY22: 113
A23: =HYPERLINK("https://arcprize.org/play?task=0962bcdd", 12) -> 12 | B23: 122 | C23: 218 | D23: 129 | E23: 217 | F23: 126 | G23: 218 | I23: 175 | J23: 132 | K23: 158 | L23: 195 | M23: 164 | Q23: 217 | R23: 140 | U23: 218 | W23: 138 | X23: 218 | Y23: 218 | Z23: 133 | AB23: 215 | AC23: 217 | AD23: 211 | AE23: 217 | AF23: 197 | AG23: 218 | AH23: 189 | AI23: 194 | AJ23: 197 | AL23: 200 | AM23: 183 | AN23: 217 | AO23: 143 | AP23: 199 | AQ23: 204 | AS23: 194 | AT23: 217 | AU23: 133 | AV23: 142 | AW23: 135 | AX23: 133 | AY23: 122
A24: =HYPERLINK("https://arcprize.org/play?task=0a938d79", 13) -> 13 | B24: 124 | C24: 253 | D24: 136 | E24: 246 | F24: 129 | G24: 239 | H24: 186 | I24: 169 | J24: 138 | K24: 153 | L24: 197 | M24: 145 | Q24: 230 | R24: 163 | U24: 1009 | W24: 161 | X24: 452 | Y24: 299 | Z24: 171 | AB24: 350 | AC24: 246 | AD24: 234 | AE24: 246 | AF24: 412 | AG24: 290 | AH24: 185 | AI24: 187 | AJ24: 199 | AL24: 246 | AM24: 205 | AN24: 246 | AO24: 136 | AP24: 212 | AQ24: 211 | AS24: 172 | AT24: 246 | AU24: 150 | AV24: 139 | AW24: 163 | AX24: 175 | AY24: 124
A25: =HYPERLINK("https://arcprize.org/play?task=0b148d64", 14) -> 14 | B25: 57 | C25: 129 | D25: 68 | E25: 129 | F25: 67 | G25: 245 | H25: 94 | I25: 108 | J25: 76 | K25: 99 | L25: 81 | M25: 76 | Q25: 124 | R25: 77 | S25: 160 | T25: 213 | U25: 255 | V25: 94 | W25: 96 | X25: 253 | Y25: 251 | Z25: 74 | AB25: 200 | AC25: 135 | AD25: 123 | AE25: 85 | AF25: 190 | AG25: 261 | AH25: 117 | AI25: 105 | AJ25: 183 | AL25: 129 | AM25: 95 | AN25: 129 | AO25: 92 | AP25: 118 | AQ25: 81 | AS25: 81 | AT25: 129 | AU25: 76 | AV25: 81 | AW25: 74 | AX25: 74 | AY25: 57
A26: =HYPERLINK("https://arcprize.org/play?task=0ca9ddb6", 15) -> 15 | B26: 92 | C26: 190 | D26: 92 | E26: 142 | F26: 87 | G26: 190 | H26: 135 | I26: 117 | J26: 104 | K26: 115 | L26: 125 | M26: 97 | Q26: 145 | R26: 116 | U26: 234 | W26: 117 | X26: 218 | Y26: 219 | Z26: 114 | AB26: 209 | AC26: 190 | AD26: 190 | AE26: 188 | AF26: 159 | AG26: 183 | AH26: 127 | AI26: 132 | AJ26: 190 | AL26: 190 | AM26: 126 | AN26: 190 | AO26: 112 | AP26: 138 | AQ26: 132 | AS26: 109 | AT26: 190 | AU26: 116 | AV26: 105 | AW26: 119 | AX26: 114 | AY26: 87
A27: =HYPERLINK("https://arcprize.org/play?task=0d3d703e", 16) -> 16 | B27: 43 | C27: 48 | D27: 43 | E27: 55 | F27: 43 | G27: 49 | H27: 46 | I27: 49 | J27: 43 | K27: 44 | L27: 46 | M27: 46 | N27: 56 | O27: 47 | Q27: 59 | R27: 49 | S27: 52 | T27: 59 | U27: 63 | V27: 50 | W27: 52 | X27: 63 | Y27: 63 | Z27: 46 | AB27: 55 | AC27: 55 | AD27: 52 | AE27: 50 | AF27: 54 | AG27: 63 | AH27: 49 | AI27: 55 | AJ27: 55 | AK27: 43 | AL27: 55 | AM27: 49 | AN27: 55 | AO27: 46 | AP27: 50 | AQ27: 49 | AS27: 50 | AT27: 55 | AU27: 46 | AV27: 46 | AW27: 46 | AX27: 44 | AY27: 43
A28: =HYPERLINK("https://arcprize.org/play?task=0dfd9992", 17) -> 17 | B28: 90 | C28: 228 | D28: 102 | E28: 256 | F28: 99 | G28: 187 | H28: 165 | I28: 149 | J28: 114 | K28: 126 | L28: 198 | M28: 147 | Q28: 291 | R28: 137 | U28: 364 | W28: 164 | X28: 291 | Y28: 297 | Z28: 133 | AB28: 183 | AC28: 256 | AE28: 256 | AF28: 253 | AG28: 216 | AH28: 155 | AI28: 158 | AJ28: 173 | AL28: 251 | AM28: 136 | AN28: 256 | AO28: 107 | AP28: 195 | AQ28: 168 | AS28: 156 | AT28: 255 | AU28: 109 | AV28: 118 | AW28: 144 | AX28: 108 | AY28: 89
A29: =HYPERLINK("https://arcprize.org/play?task=0e206a2e", 18) -> 18 | B29: 301 | C29: 539 | D29: 275 | E29: 483 | F29: 286 | G29: 531 | I29: 519 | J29: 338 | K29: 322 | L29: 385 | M29: 389 | Q29: 622 | R29: 354 | Y29: 686 | Z29: 361 | AB29: 593 | AC29: 488 | AE29: 491 | AF29: 799 | AG29: 1288 | AH29: 455 | AI29: 339 | AJ29: 392 | AL29: 488 | AM29: 384 | AN29: 483 | AO29: 346 | AP29: 435 | AQ29: 426 | AS29: 342 | AT29: 483 | AU29: 311 | AV29: 299 | AW29: 332 | AX29: 392 | AY29: 268
A30: =HYPERLINK("https://arcprize.org/play?task=10fcaaa3", 19) -> 19 | B30: 103 | C30: 250 | D30: 104 | E30: 229 | F30: 105 | G30: 179 | H30: 141 | I30: 130 | J30: 121 | K30: 139 | L30: 141 | M30: 116 | Q30: 250 | R30: 140 | S30: 168 | U30: 279 | W30: 141 | X30: 247 | Y30: 248 | Z30: 121 | AB30: 203 | AC30: 229 | AE30: 229 | AF30: 247 | AG30: 250 | AH30: 171 | AI30: 175 | AJ30: 175 | AL30: 229 | AM30: 168 | AN30: 229 | AO30: 121 | AP30: 177 | AQ30: 174 | AS30: 140 | AT30: 225 | AU30: 119 | AV30: 121 | AW30: 134 | AX30: 128 | AY30: 103
A31: =HYPERLINK("https://arcprize.org/play?task=11852cab", 20) -> 20 | B31: 138 | C31: 310 | D31: 139 | E31: 265 | F31: 135 | G31: 289 | I31: 226 | J31: 156 | K31: 156 | L31: 215 | M31: 177 | Q31: 299 | R31: 168 | U31: 357 | W31: 227 | X31: 297 | Y31: 310 | Z31: 195 | AB31: 297 | AC31: 265 | AE31: 265 | AF31: 297 | AG31: 239 | AH31: 196 | AI31: 201 | AJ31: 205 | AL31: 265 | AM31: 218 | AN31: 265 | AO31: 126 | AP31: 226 | AQ31: 199 | AS31: 184 | AT31: 265 | AU31: 152 | AV31: 138 | AW31: 133 | AX31: 157 | AY31: 121
A32: =HYPERLINK("https://arcprize.org/play?task=1190e5a7", 21) -> 21 | B32: 52 | C32: 77 | D32: 51 | E32: 79 | F32: 52 | G32: 79 | H32: 74 | I32: 76 | J32: 58 | K32: 67 | L32: 76 | M32: 55 | Q32: 80 | R32: 71 | S32: 83 | T32: 81 | U32: 248 | V32: 77 | W32: 71 | X32: 220 | Y32: 219 | Z32: 67 | AB32: 79 | AC32: 79 | AD32: 76 | AE32: 79 | AF32: 220 | AG32: 79 | AH32: 77 | AI32: 76 | AJ32: 79 | AK32: 62 | AL32: 79 | AM32: 67 | AN32: 79 | AO32: 51 | AP32: 79 | AQ32: 79 | AS32: 75 | AT32: 79 | AU32: 52 | AV32: 54 | AW32: 54 | AX32: 71 | AY32: 51
A33: =HYPERLINK("https://arcprize.org/play?task=137eaa0f", 22) -> 22 | B33: 91 | C33: 212 | D33: 95 | E33: 206 | F33: 92 | G33: 225 | I33: 108 | J33: 106 | K33: 103 | L33: 104 | M33: 104 | Q33: 136 | R33: 103 | S33: 107 | U33: 224 | V33: 106 | W33: 102 | X33: 225 | Y33: 217 | Z33: 106 | AB33: 225 | AC33: 206 | AE33: 206 | AF33: 225 | AG33: 164 | AH33: 108 | AI33: 108 | AJ33: 108 | AL33: 206 | AM33: 109 | AN33: 206 | AO33: 101 | AP33: 105 | AQ33: 109 | AS33: 108 | AT33: 206 | AU33: 106 | AV33: 97 | AW33: 99 | AX33: 103 | AY33: 91
A34: =HYPERLINK("https://arcprize.org/play?task=150deff5", 23) -> 23 | B34: 195 | C34: 326 | D34: 182 | E34: 295 | F34: 197 | G34: 314 | I34: 285 | J34: 225 | K34: 222 | L34: 295 | M34: 220 | R34: 254 | Y34: 320 | Z34: 229 | AB34: 341 | AC34: 295 | AE34: 295 | AF34: 383 | AG34: 565 | AH34: 234 | AI34: 295 | AJ34: 309 | AK34: 204 | AL34: 295 | AM34: 265 | AN34: 295 | AO34: 191 | AP34: 244 | AQ34: 261 | AS34: 242 | AT34: 294 | AU34: 250 | AV34: 206 | AW34: 208 | AX34: 244 | AY34: 181
A35: =HYPERLINK("https://arcprize.org/play?task=178fcbfb", 24) -> 24 | B35: 62 | C35: 144 | D35: 62 | E35: 144 | F35: 62 | G35: 145 | H35: 68 | I35: 90 | J35: 62 | K35: 66 | L35: 67 | M35: 62 | Q35: 70 | R35: 69 | S35: 111 | T35: 162 | U35: 151 | V35: 67 | W35: 62 | X35: 156 | Y35: 156 | Z35: 65 | AB35: 156 | AC35: 144 | AD35: 69 | AE35: 144 | AF35: 156 | AG35: 147 | AH35: 63 | AI35: 70 | AJ35: 94 | AL35: 120 | AM35: 68 | AN35: 144 | AO35: 62 | AP35: 68 | AQ35: 71 | AS35: 65 | AT35: 144 | AU35: 62 | AV35: 62 | AW35: 62 | AX35: 65 | AY35: 62
A36: =HYPERLINK("https://arcprize.org/play?task=1a07d186", 25) -> 25 | B36: 127 | C36: 305 | D36: 134 | E36: 275 | F36: 141 | G36: 276 | I36: 230 | J36: 177 | K36: 138 | L36: 219 | M36: 192 | Q36: 265 | R36: 180 | U36: 580 | W36: 177 | Y36: 341 | Z36: 161 | AB36: 269 | AC36: 275 | AE36: 248 | AF36: 295 | AG36: 386 | AH36: 229 | AI36: 211 | AJ36: 224 | AL36: 275 | AM36: 211 | AN36: 275 | AO36: 138 | AP36: 211 | AQ36: 213 | AS36: 211 | AT36: 275 | AU36: 156 | AV36: 144 | AW36: 192 | AX36: 180 | AY36: 127
A37: =HYPERLINK("https://arcprize.org/play?task=1b2d62fb", 26) -> 26 | B37: 50 | C37: 57 | D37: 52 | E37: 57 | F37: 50 | G37: 57 | H37: 57 | I37: 57 | J37: 52 | K37: 52 | L37: 54 | M37: 52 | Q37: 58 | R37: 55 | S37: 73 | T37: 57 | U37: 59 | V37: 57 | W37: 55 | X37: 59 | Y37: 59 | Z37: 52 | AB37: 59 | AC37: 57 | AD37: 57 | AE37: 57 | AF37: 59 | AG37: 59 | AH37: 54 | AI37: 57 | AJ37: 57 | AK37: 54 | AL37: 57 | AM37: 57 | AN37: 57 | AO37: 52 | AP37: 57 | AQ37: 54 | AS37: 57 | AT37: 57 | AU37: 50 | AV37: 52 | AW37: 50 | AX37: 52 | AY37: 50
A38: =HYPERLINK("https://arcprize.org/play?task=1b60fb0c", 27) -> 27 | B38: 97 | C38: 315 | D38: 103 | E38: 316 | F38: 105 | G38: 399 | I38: 117 | J38: 125 | K38: 125 | L38: 105 | M38: 105 | Q38: 258 | R38: 124 | T38: 146 | W38: 107 | Y38: 366 | Z38: 121 | AB38: 287 | AC38: 325 | AE38: 138 | AF38: 231 | AG38: 226 | AH38: 140 | AI38: 222 | AJ38: 259 | AK38: 112 | AL38: 251 | AM38: 176 | AN38: 319 | AO38: 103 | AP38: 200 | AQ38: 169 | AS38: 129 | AT38: 316 | AU38: 113 | AV38: 104 | AW38: 105 | AX38: 122 | AY38: 97
A39: =HYPERLINK("https://arcprize.org/play?task=1bfc4729", 28) -> 28 | B39: 63 | C39: 132 | D39: 66 | E39: 139 | F39: 63 | G39: 139 | H39: 81 | I39: 99 | J39: 78 | K39: 78 | L39: 80 | M39: 63 | Q39: 97 | R39: 71 | S39: 106 | T39: 90 | U39: 139 | V39: 86 | W39: 64 | X39: 139 | Y39: 139 | Z39: 80 | AB39: 132 | AC39: 139 | AD39: 85 | AE39: 139 | AF39: 138 | AG39: 135 | AH39: 74 | AI39: 79 | AJ39: 84 | AL39: 119 | AM39: 80 | AN39: 139 | AO39: 64 | AP39: 100 | AQ39: 98 | AS39: 82 | AT39: 139 | AU39: 70 | AV39: 70 | AW39: 70 | AX39: 77 | AY39: 63
A40: =HYPERLINK("https://arcprize.org/play?task=1c786137", 29) -> 29 | B40: 103 | C40: 229 | D40: 110 | E40: 223 | F40: 108 | G40: 239 | I40: 213 | J40: 121 | K40: 117 | L40: 126 | M40: 121 | Q40: 256 | R40: 134 | U40: 403 | W40: 108 | Y40: 239 | Z40: 131 | AB40: 237 | AC40: 223 | AE40: 223 | AF40: 249 | AG40: 329 | AH40: 172 | AI40: 197 | AJ40: 197 | AL40: 205 | AM40: 174 | AN40: 223 | AO40: 141 | AP40: 177 | AQ40: 192 | AS40: 132 | AT40: 194 | AU40: 117 | AV40: 113 | AW40: 142 | AX40: 159 | AY40: 103
A41: =HYPERLINK("https://arcprize.org/play?task=1caeab9d", 30) -> 30 | B41: 93 | C41: 233 | D41: 94 | E41: 212 | F41: 93 | G41: 226 | I41: 120 | J41: 94 | K41: 94 | L41: 150 | M41: 112 | Q41: 227 | R41: 106 | U41: 240 | W41: 94 | X41: 232 | Y41: 233 | Z41: 117 | AB41: 217 | AC41: 212 | AE41: 212 | AF41: 226 | AG41: 216 | AH41: 152 | AI41: 189 | AJ41: 194 | AL41: 212 | AM41: 170 | AN41: 212 | AO41: 116 | AP41: 193 | AQ41: 168 | AS41: 121 | AT41: 212 | AU41: 93 | AV41: 116 | AW41: 116 | AX41: 94 | AY41: 91
A42: =HYPERLINK("https://arcprize.org/play?task=1cf80156", 31) -> 31 | B42: 45 | C42: 126 | D42: 45 | E42: 51 | F42: 45 | G42: 61 | H42: 59 | I42: 60 | J42: 50 | K42: 48 | L42: 48 | M42: 45 | P42: 107 | Q42: 87 | R42: 50 | S42: 88 | T42: 177 | U42: 126 | V42: 50 | W42: 47 | X42: 126 | Y42: 126 | Z42: 50 | AB42: 126 | AC42: 126 | AD42: 51 | AE42: 48 | AF42: 126 | AG42: 126 | AH42: 51 | AI42: 50 | AJ42: 67 | AK42: 50 | AL42: 54 | AM42: 50 | AN42: 126 | AO42: 50 | AP42: 50 | AQ42: 50 | AS42: 48 | AT42: 126 | AU42: 50 | AV42: 48 | AW42: 48 | AX42: 50 | AY42: 45
...

Sheet Post-comp diamonds
F1: Competition Best | G1: Post-comp best | H1: Δ | J1: Total Δ | K1: =sum(D2:D401) -> 280
A2: =Scores!A12 -> 1 | B2: =Compilation!B9 -> 58 | C2: =Scores!AY12 -> 58 | D2: =B2-C2 -> 0 | E2: {=sort(A2:D401,4,false)} -> 277 | F2: 155 | G2: 109 | H2: 46 | J2: Score | K2: =1000000-sum(C2:C401) -> 963477
A3: =Scores!A13 -> 2 | B3: =Compilation!B10 -> 86 | C3: =Scores!AY13 -> 85 | D3: =B3-C3 -> 1 | E3: 255 | F3: 212 | G3: 194 | H3: 18
A4: =Scores!A14 -> 3 | B4: =Compilation!B11 -> 58 | C4: =Scores!AY14 -> 58 | D4: =B4-C4 -> 0 | E4: 349 | F4: 172 | G4: 162 | H4: 10
A5: =Scores!A15 -> 4 | B5: =Compilation!B12 -> 73 | C5: =Scores!AY15 -> 73 | D5: =B5-C5 -> 0 | E5: 324 | F5: 216 | G5: 207 | H5: 9
A6: =Scores!A16 -> 5 | B6: =Compilation!B13 -> 166 | C6: =Scores!AY16 -> 166 | D6: =B6-C6 -> 0 | E6: 387 | F6: 192 | G6: 183 | H6: 9
A7: =Scores!A17 -> 6 | B7: =Compilation!B14 -> 49 | C7: =Scores!AY17 -> 49 | D7: =B7-C7 -> 0 | E7: 80 | F7: 231 | G7: 223 | H7: 8
A8: =Scores!A18 -> 7 | B8: =Compilation!B15 -> 62 | C8: =Scores!AY18 -> 62 | D8: =B8-C8 -> 0 | E8: 154 | F8: 96 | G8: 88 | H8: 8
A9: =Scores!A19 -> 8 | B9: =Compilation!B16 -> 84 | C9: =Scores!AY19 -> 83 | D9: =B9-C9 -> 1 | E9: 219 | F9: 241 | G9: 233 | H9: 8
A10: =Scores!A20 -> 9 | B10: =Compilation!B17 -> 95 | C10: =Scores!AY20 -> 95 | D10: =B10-C10 -> 0 | E10: 18 | F10: 275 | G10: 268 | H10: 7
A11: =Scores!A21 -> 10 | B11: =Compilation!B18 -> 66 | C11: =Scores!AY21 -> 66 | D11: =B11-C11 -> 0 | E11: 157 | F11: 237 | G11: 230 | H11: 7
A12: =Scores!A22 -> 11 | B12: =Compilation!B19 -> 114 | C12: =Scores!AY22 -> 113 | D12: =B12-C12 -> 1 | E12: 158 | F12: 260 | G12: 253 | H12: 7
A13: =Scores!A23 -> 12 | B13: =Compilation!B20 -> 122 | C13: =Scores!AY23 -> 122 | D13: =B13-C13 -> 0 | E13: 196 | F13: 105 | G13: 99 | H13: 6
A14: =Scores!A24 -> 13 | B14: =Compilation!B21 -> 124 | C14: =Scores!AY24 -> 124 | D14: =B14-C14 -> 0 | E14: 366 | F14: 301 | G14: 295 | H14: 6
... A401: =Scores!A411 -> 400 | B401: =Compilation!B408 -> 66 | C401: =Scores!AY411 -> 66 | D401: =B401-C401 -> 0 | E401: 400 | F401: 66 | G401: 66 | H401: 0

Sheet Compilation
B1: BEST | C1: AVERAGE | D1: TOTAL | E1: WORST | S1: SHORTEST | W1: LONGEST | AA1: SOLUTIONS
K2: ox jam | L2: has solved | M2: =K4/400 -> 1 | N2: of all tasks
A3: SCORE | B3: =sum(C9:C408) -> 963197 | C3: =AVERAGE(Scores!B2:AE2) -> 761149.57 | D3: =sum(Scores!B2:AE2) -> 37296329 | E3: {=sum(byrow(Scores!B12:AE411,lambda(row,let(score,max(row),if(score,max(2500-score,1),0)))))} -> 867129 | K3: SOLVED | L3: UNSOLVED
A4: COUNT | B4: =IFERROR(__xludf.DUMMYFUNCTION("rows(filter(A9:A408,not(B9:B408="""")))"),400.0) -> 400 | C4: =AVERAGE(Scores!B4:AE4) -> 323.73469 | D4: =IFERROR(__xludf.DUMMYFUNCTION("rows(let(a,FLATTEN(Scores!B12:AE411),filter(a,a)))"),15863.0) -> 15863 | E4: 400 | K4: =IFERROR(__xludf.DUMMYFUNCTION("rows(filter(K9:K408,K9:K408))"),400.0) -> 400 | L4: =IFERROR(__xludf.DUMMYFUNCTION("IFERROR(ROWS(FILTER(L9:L408, L9:L408)), 0) "),0.0) -> 0
A5: SUM | B5: =sum(B9:B408) -> 36803 | C5: =AVERAGE(Scores!B5:AE5) -> 48217.184 | D5: =IFERROR(__xludf.DUMMYFUNCTION("SUM(FLATTEN(Scores!B12:AE411))"),2362642.0) -> 2362642 | E5: {=sum(byrow(Scores!B12:AE411,lambda(row,max(row))))} -> 134342
A6: AVG | B6: =AVERAGE(B9:B408) -> 92.0075 | C6: =AVERAGE(Scores!B6:AE6) -> 143.64994 | D6: =IFERROR(__xludf.DUMMYFUNCTION("AVERAGE(let(a,FLATTEN(Scores!B12:AE411),filter(a,a)))"),148.94042740969553) -> 148.94043 | E6: {=AVERAGE(byrow(Scores!B12:AE411,lambda(row,max(row))))} -> 335.855
A8: TASK | B8: BEST | C8: SCORE | D8: LEADER | E8: 💎 | F8: 🥇 | G8: 🥈 | H8: 🥉 | I8: SOLUTIONS | J8: GOLDS | K8: TASK | L8: TASK | O8: Length | P8: Count | S8: TASK | T8: LENGTH | U8: SCORE | W8: TASK | X8: LENGTH | Y8: SCORE | AA8: TASK | AB8: SOLUTIONS | AC8: LENGTH
A9: =HYPERLINK("https://arcprize.org/play?task=007bbfb7", 1) -> 1 | B9: =IFERROR(__xludf.DUMMYFUNCTION("min(filter(Scores!B12:AX12,Scores!B12:AX12>0))"),58.0) -> 58 | C9: {=IF(B9:B408="","",IF(2500-B9:B408<=1,1,2500-B9:B408))} -> 2442 | D9: {=if(B9,if(countif(Scores!B12:AX12,B9)=1,concat("💎",XLOOKUP(B9,Scores!B12:AX12,Scores!B$1:AX$1)),concat("🥇 x",countif(Scores!B12:AX12,B9))),"")} -> 🥇 x3 | E9: =if(countif(Scores!B12:AX12,B9)=1,F9,-1) -> -1 | F9: =if(B9,B9,-1) -> 58 | G9: =IFERROR(__xludf.DUMMYFUNCTION("if(iferror(small(filter(Scores!B12:AX12,Scores!B12:AX12>0),2),-1)<>F9,iferror(small(filter(Scores!B12:AX12,Scores!B12:AX12>0),2),-1),-1)"),-1.0) -> -1 | H9: =IFERROR(__xludf.DUMMYFUNCTION("if(iferror(small(filter(Scores!B12:AX12,Scores!B12:AX12>0),3),-1)<>iferror(small(filter(Scores!B12:AX12,Scores!B12:AX12>0),2),-1),iferror(small(filter(Scores!B12:AX12,Scores!B12:AX12>0),3),-1),-1)"),-1.0) -> -1 | I9: =IFERROR(__xludf.DUMMYFUNCTION("IFERROR(COLUMNS(filter(Scores!B12:AE12,Scores!B12:AE12)),"""")"),48.0) -> 48 | J9: =COUNTIF(Scores!B12:AX12,B9) -> 3 | K9: =IFERROR(__xludf.DUMMYFUNCTION("let(a,xlookup(K2,Scores!B1:AE1,Scores!B12:AE411),filter(A9:A408,not(a="""")))"),1.0) -> 1 | L9: =IFERROR(__xludf.DUMMYFUNCTION("IFERROR(LET(a, XLOOKUP(K2, Scores!B1:AE1, Scores!B12:AE411), FILTER(A9:A408, a="""")), """") "),"") | N9: 1 | O9: =CONCATENATE(N9,IF(N10<1000,concat("-",N10-1),"+")) -> 1-9 | P9: =countif($B$9:$B$408,concat(">=",N9))-countif($B$9:$B$408,concat(">=",N10)) -> 0 | S9: {=sort(A9:C408,2,true)} -> 155 | T9: 18 | U9: 2482 | W9: {=sort(A9:C408,2,false)} -> 366 | X9: 301 | Y9: 2199 | AA9: {=sort({A9:A408,I9:I408,B9:B408},2,true,3,false)} -> 219 | AB9: 33 | AC9: 241
A10: =HYPERLINK("https://arcprize.org/play?task=00d62c1b", 2) -> 2 | B10: =IFERROR(__xludf.DUMMYFUNCTION("min(filter(Scores!B13:AX13,Scores!B13:AX13>0))"),86.0) -> 86 | C10: 2414 | D10: {=if(B10,if(countif(Scores!B13:AX13,B10)=1,concat("💎",XLOOKUP(B10,Scores!B13:AX13,Scores!B$1:AX$1)),concat("🥇 x",countif(Scores!B13:AX13,B10))),"")} -> 💎jailctf merger | E10: =if(countif(Scores!B13:AX13,B10)=1,F10,-1) -> 86 | F10: =if(B10,B10,-1) -> 86 | G10: =IFERROR(__xludf.DUMMYFUNCTION("if(iferror(small(filter(Scores!B13:AX13,Scores!B13:AX13>0),2),-1)<>F10,iferror(small(filter(Scores!B13:AX13,Scores!B13:AX13>0),2),-1),-1)"),88.0) -> 88 | H10: =IFERROR(__xludf.DUMMYFUNCTION("if(iferror(small(filter(Scores!B13:AX13,Scores!B13:AX13>0),3),-1)<>iferror(small(filter(Scores!B13:AX13,Scores!B13:AX13>0),2),-1),iferror(small(filter(Scores!B13:AX13,Scores!B13:AX13>0),3),-1),-1)"),-1.0) -> -1 | I10: =IFERROR(__xludf.DUMMYFUNCTION("IFERROR(COLUMNS(filter(Scores!B13:AE13,Scores!B13:AE13)),"""")"),45.0) -> 45 | J10: =COUNTIF(Scores!B13:AX13,B10) -> 1 | K10: =IFERROR(__xludf.DUMMYFUNCTION("""COMPUTED_VALUE"""),2.0) -> 2 | N10: 10 | O10: =CONCATENATE(N10,IF(N11<1000,concat("-",N11-1),"+")) -> 10-19 | P10: =countif($B$9:$B$408,concat(">=",N10))-countif($B$9:$B$408,concat(">=",N11)) -> 1 | S10: 116 | T10: 20 | U10: 2480 | W10: 96 | X10: 282 | Y10: 2218 | AA10: 285 | AB10: 33 | AC10: 226
A11: =HYPERLINK("https://arcprize.org/play?task=017c7c7b", 3) -> 3 | B11: =IFERROR(__xludf.DUMMYFUNCTION("min(filter(Scores!B14:AX14,Scores!B14:AX14>0))"),58.0) -> 58 | C11: 2442 | D11: {=if(B11,if(countif(Scores!B14:AX14,B11)=1,concat("💎",XLOOKUP(B11,Scores!B14:AX14,Scores!B$1:AX$1)),concat("🥇 x",countif(Scores!B14:AX14,B11))),"")} -> 🥇 x11 | E11: =if(countif(Scores!B14:AX14,B11)=1,F11,-1) -> -1 | F11: =if(B11,B11,-1) -> 58 | G11: =IFERROR(__xludf.DUMMYFUNCTION("if(iferror(small(filter(Scores!B14:AX14,Scores!B14:AX14>0),2),-1)<>F11,iferror(small(filter(Scores!B14:AX14,Scores!B14:AX14>0),2),-1),-1)"),-1.0) -> -1 | H11: =IFERROR(__xludf.DUMMYFUNCTION("if(iferror(small(filter(Scores!B14:AX14,Scores!B14:AX14>0),3),-1)<>iferror(small(filter(Scores!B14:AX14,Scores!B14:AX14>0),2),-1),iferror(small(filter(Scores!B14:AX14,Scores!B14:AX14>0),3),-1),-1)"),-1.0) -> -1 | I11: =IFERROR(__xludf.DUMMYFUNCTION("IFERROR(COLUMNS(filter(Scores!B14:AE14,Scores!B14:AE14)),"""")"),46.0) -> 46 | J11: =COUNTIF(Scores!B14:AX14,B11) -> 11 | K11: =IFERROR(__xludf.DUMMYFUNCTION("""COMPUTED_VALUE"""),3.0) -> 3 | N11: =N10+10 -> 20 | O11: =CONCATENATE(N11,IF(N12<1000,concat("-",N12-1),"+")) -> 20-29 | P11: =countif($B$9:$B$408,concat(">=",N11))-countif($B$9:$B$408,concat(">=",N12)) -> 11 | S11: 172 | T11: 20 | U11: 2480 | W11: 18 | X11: 275 | Y11: 2225 | AA11: 255 | AB11: 33 | AC11: 212
A12: =HYPERLINK("https://arcprize.org/play?task=025d127b", 4) -> 4 | B12: =IFERROR(__xludf.DUMMYFUNCTION("min(filter(Scores!B15:AX15,Scores!B15:AX15>0))"),73.0) -> 73 | C12: 2427 | D12: {=if(B12,if(countif(Scores!B15:AX15,B12)=1,concat("💎",XLOOKUP(B12,Scores!B15:AX15,Scores!B$1:AX$1)),concat("🥇 x",countif(Scores!B15:AX15,B12))),"")} -> 💎ox jam | E12: =if(countif(Scores!B15:AX15,B12)=1,F12,-1) -> 73 | F12: =if(B12,B12,-1) -> 73 | G12: =IFERROR(__xludf.DUMMYFUNCTION("if(iferror(small(filter(Scores!B15:AX15,Scores!B15:AX15>0),2),-1)<>F12,iferror(small(filter(Scores!B15:AX15,Scores!B15:AX15>0),2),-1),-1)"),74.0) -> 74 | H12: =IFERROR(__xludf.DUMMYFUNCTION("if(iferror(small(filter(Scores!B15:AX15,Scores!B15:AX15>0),3),-1)<>iferror(small(filter(Scores!B15:AX15,Scores!B15:AX15>0),2),-1),iferror(small(filter(Scores!B15:AX15,Scores!B15:AX15>0),3),-1),-1)"),79.0) -> 79 | I12: =IFERROR(__xludf.DUMMYFUNCTION("IFERROR(COLUMNS(filter(Scores!B15:AE15,Scores!B15:AE15)),"""")"),42.0) -> 42 | J12: =COUNTIF(Scores!B15:AX15,B12) -> 1 | K12: =IFERROR(__xludf.DUMMYFUNCTION("""COMPUTED_VALUE"""),4.0) -> 4 | N12: =N11+10 -> 30 | O12: =CONCATENATE(N12,IF(N13<1000,concat("-",N13-1),"+")) -> 30-39 | P12: =countif($B$9:$B$408,concat(">=",N12))-countif($B$9:$B$408,concat(">=",N13)) -> 18 | S12: 210 | T12: 20 | U12: 2480 | W12: 133 | X12: 273 | Y12: 2227 | AA12: 86 | AB12: 33 | AC12: 151
A13: =HYPERLINK("https://arcprize.org/play?task=045e512c", 5) -> 5 | B13: =IFERROR(__xludf.DUMMYFUNCTION("min(filter(Scores!B16:AX16,Scores!B16:AX16>0))"),166.0) -> 166 | C13: 2334 | D13: {=if(B13,if(countif(Scores!B16:AX16,B13)=1,concat("💎",XLOOKUP(B13,Scores!B16:AX16,Scores!B$1:AX$1)),concat("🥇 x",countif(Scores!B16:AX16,B13))),"")} -> 💎jailctf merger | E13: =if(countif(Scores!B16:AX16,B13)=1,F13,-1) -> 166 | F13: =if(B13,B13,-1) -> 166 | G13: =IFERROR(__xludf.DUMMYFUNCTION("if(iferror(small(filter(Scores!B16:AX16,Scores!B16:AX16>0),2),-1)<>F13,iferror(small(filter(Scores!B16:AX16,Scores!B16:AX16>0),2),-1),-1)"),174.0) -> 174 | H13: =IFERROR(__xludf.DUMMYFUNCTION("if(iferror(small(filter(Scores!B16:AX16,Scores!B16:AX16>0),3),-1)<>iferror(small(filter(Scores!B16:AX16,Scores!B16:AX16>0),2),-1),iferror(small(filter(Scores!B16:AX16,Scores!B16:AX16>0),3),-1),-1)"),199.0) -> 199 | I13: =IFERROR(__xludf.DUMMYFUNCTION("IFERROR(COLUMNS(filter(Scores!B16:AE16,Scores!B16:AE16)),"""")"),38.0) -> 38 | J13: =COUNTIF(Scores!B16:AX16,B13) -> 1 | K13: =IFERROR(__xludf.DUMMYFUNCTION("""COMPUTED_VALUE"""),5.0) -> 5 | N13: =N12+10 -> 40 | O13: =CONCATENATE(N13,IF(N14<1000,concat("-",N14-1),"+")) -> 40-49 | P13: =countif($B$9:$B$408,concat(">=",N13))-countif($B$9:$B$408,concat(">=",N14)) -> 29 | S13: 53 | T13: 21 | U13: 2479 | W13: 54 | X13: 266 | Y13: 2234 | AA13: 205 | AB13: 33 | AC13: 134
A14: =HYPERLINK("https://arcprize.org/play?task=0520fde7", 6) -> 6 | B14: =IFERROR(__xludf.DUMMYFUNCTION("min(filter(Scores!B17:AX17,Scores!B17:AX17>0))"),49.0) -> 49 | C14: 2451 | D14: {=if(B14,if(countif(Scores!B17:AX17,B14)=1,concat("💎",XLOOKUP(B14,Scores!B17:AX17,Scores!B$1:AX$1)),concat("🥇 x",countif(Scores!B17:AX17,B14))),"")} -> 🥇 x4 | E14: =if(countif(Scores!B17:AX17,B14)=1,F14,-1) -> -1 | F14: =if(B14,B14,-1) -> 49 | G14: =IFERROR(__xludf.DUMMYFUNCTION("if(iferror(small(filter(Scores!B17:AX17,Scores!B17:AX17>0),2),-1)<>F14,iferror(small(filter(Scores!B17:AX17,Scores!B17:AX17>0),2),-1),-1)"),-1.0) -> -1 | H14: =IFERROR(__xludf.DUMMYFUNCTION("if(iferror(small(filter(Scores!B17:AX17,Scores!B17:AX17>0),3),-1)<>iferror(small(filter(Scores!B17:AX17,Scores!B17:AX17>0),2),-1),iferror(small(filter(Scores!B17:AX17,Scores!B17:AX17>0),3),-1),-1)"),-1.0) -> -1 | I14: =IFERROR(__xludf.DUMMYFUNCTION("IFERROR(COLUMNS(filter(Scores!B17:AE17,Scores!B17:AE17)),"""")"),47.0) -> 47 | J14: =COUNTIF(Scores!B17:AX17,B14) -> 4 | K14: =IFERROR(__xludf.DUMMYFUNCTION("""COMPUTED_VALUE"""),6.0) -> 6 | N14: =N13+10 -> 50 | O14: =CONCATENATE(N14,IF(N15<1000,concat("-",N15-1),"+")) -> 50-59 | P14: =countif($B$9:$B$408,concat(">=",N14))-countif($B$9:$B$408,concat(">=",N15)) -> 49 | S14: 179 | T14: 21 | U14: 2479 | W14: 233 | X14: 261 | Y14: 2239 | AA14: 367 | AB14: 33 | AC14: 126
A15: =HYPERLINK("https://arcprize.org/play?task=05269061", 7) -> 7 | B15: =IFERROR(__xludf.DUMMYFUNCTION("min(filter(Scores!B18:AX18,Scores!B18:AX18>0))"),62.0) -> 62 | C15: 2438 | D15: {=if(B15,if(countif(Scores!B18:AX18,B15)=1,concat("💎",XLOOKUP(B15,Scores!B18:AX18,Scores!B$1:AX$1)),concat("🥇 x",countif(Scores!B18:AX18,B15))),"")} -> 🥇 x2 | E15: =if(countif(Scores!B18:AX18,B15)=1,F15,-1) -> -1 | F15: =if(B15,B15,-1) -> 62 | G15: =IFERROR(__xludf.DUMMYFUNCTION("if(iferror(small(filter(Scores!B18:AX18,Scores!B18:AX18>0),2),-1)<>F15,iferror(small(filter(Scores!B18:AX18,Scores!B18:AX18>0),2),-1),-1)"),-1.0) -> -1 | H15: =IFERROR(__xludf.DUMMYFUNCTION("if(iferror(small(filter(Scores!B18:AX18,Scores!B18:AX18>0),3),-1)<>iferror(small(filter(Scores!B18:AX18,Scores!B18:AX18>0),2),-1),iferror(small(filter(Scores!B18:AX18,Scores!B18:AX18>0),3),-1),-1)"),63.0) -> 63 | I15: =IFERROR(__xludf.DUMMYFUNCTION("IFERROR(COLUMNS(filter(Scores!B18:AE18,Scores!B18:AE18)),"""")"),44.0) -> 44 | J15: =COUNTIF(Scores!B18:AX18,B15) -> 2 | K15: =IFERROR(__xludf.DUMMYFUNCTION("""COMPUTED_VALUE"""),7.0) -> 7 | N15: =N14+10 -> 60 | O15: =CONCATENATE(N15,IF(N16<1000,concat("-",N16-1),"+")) -> 60-69 | P15: =countif($B$9:$B$408,concat(">=",N15))-countif($B$9:$B$408,concat(">=",N16)) -> 47 | S15: 241 | T15: 21 | U15: 2479 | W15: 158 | X15: 260 | Y15: 2240 | AA15: 76 | AB15: 34 | AC15: 258
A16: =HYPERLINK("https://arcprize.org/play?task=05f2a901", 8) -> 8 | B16: =IFERROR(__xludf.DUMMYFUNCTION("min(filter(Scores!B19:AX19,Scores!B19:AX19>0))"),84.0) -> 84 | C16: 2416 | D16: {=if(B16,if(countif(Scores!B19:AX19,B16)=1,concat("💎",XLOOKUP(B16,Scores!B19:AX19,Scores!B$1:AX$1)),concat("🥇 x",countif(Scores!B19:AX19,B16))),"")} -> 🥇 x2 | E16: =if(countif(Scores!B19:AX19,B16)=1,F16,-1) -> -1 | F16: =if(B16,B16,-1) -> 84 | G16: =IFERROR(__xludf.DUMMYFUNCTION("if(iferror(small(filter(Scores!B19:AX19,Scores!B19:AX19>0),2),-1)<>F16,iferror(small(filter(Scores!B19:AX19,Scores!B19:AX19>0),2),-1),-1)"),-1.0) -> -1 | H16: =IFERROR(__xludf.DUMMYFUNCTION("if(iferror(small(filter(Scores!B19:AX19,Scores!B19:AX19>0),3),-1)<>iferror(small(filter(Scores!B19:AX19,Scores!B19:AX19>0),2),-1),iferror(small(filter(Scores!B19:AX19,Scores!B19:AX19>0),3),-1),-1)"),90.0) -> 90 | I16: =IFERROR(__xludf.DUMMYFUNCTION("IFERROR(COLUMNS(filter(Scores!B19:AE19,Scores!B19:AE19)),"""")"),40.0) -> 40 | J16: =COUNTIF(Scores!B19:AX19,B16) -> 2 | K16: =IFERROR(__xludf.DUMMYFUNCTION("""COMPUTED_VALUE"""),8.0) -> 8 | N16: =N15+10 -> 70 | O16: =CONCATENATE(N16,IF(N17<1000,concat("-",N17-1),"+")) -> 70-79 | P16: =countif($B$9:$B$408,concat(">=",N16))-countif($B$9:$B$408,concat(">=",N17)) -> 34 | S16: 113 | T16: 25 | U16: 2475 | W16: 76 | X16: 258 | Y16: 2242 | AA16: 101 | AB16: 34 | AC16: 258
A17: =HYPERLINK("https://arcprize.org/play?task=06df4c85", 9) -> 9 | B17: =IFERROR(__xludf.DUMMYFUNCTION("min(filter(Scores!B20:AX20,Scores!B20:AX20>0))"),95.0) -> 95 | C17: 2405 | D17: {=if(B17,if(countif(Scores!B20:AX20,B17)=1,concat("💎",XLOOKUP(B17,Scores!B20:AX20,Scores!B$1:AX$1)),concat("🥇 x",countif(Scores!B20:AX20,B17))),"")} -> 💎Code Golf International | E17: =if(countif(Scores!B20:AX20,B17)=1,F17,-1) -> 95 | F17: =if(B17,B17,-1) -> 95 | G17: =IFERROR(__xludf.DUMMYFUNCTION("if(iferror(small(filter(Scores!B20:AX20,Scores!B20:AX20>0),2),-1)<>F17,iferror(small(filter(Scores!B20:AX20,Scores!B20:AX20>0),2),-1),-1)"),107.0) -> 107 | H17: =IFERROR(__xludf.DUMMYFUNCTION("if(iferror(small(filter(Scores!B20:AX20,Scores!B20:AX20>0),3),-1)<>iferror(small(filter(Scores!B20:AX20,Scores!B20:AX20>0),2),-1),iferror(small(filter(Scores!B20:AX20,Scores!B20:AX20>0),3),-1),-1)"),108.0) -> 108 | I17: =IFERROR(__xludf.DUMMYFUNCTION("IFERROR(COLUMNS(filter(Scores!B20:AE20,Scores!B20:AE20)),"""")"),41.0) -> 41 | J17: =COUNTIF(Scores!B20:AX20,B17) -> 1 | K17: =IFERROR(__xludf.DUMMYFUNCTION("""COMPUTED_VALUE"""),9.0) -> 9 | N17: =N16+10 -> 80 | O17: =CONCATENATE(N17,IF(N18<1000,concat("-",N18-1),"+")) -> 80-89 | P17: =countif($B$9:$B$408,concat(">=",N17))-countif($B$9:$B$408,concat(">=",N18)) -> 43 | S17: 385 | T17: 25 | U17: 2475 | W17: 101 | X17: 258 | Y17: 2242 | AA17: 209 | AB17: 34 | AC17: 247
A18: =HYPERLINK("https://arcprize.org/play?task=08ed6ac7", 10) -> 10 | B18: =IFERROR(__xludf.DUMMYFUNCTION("min(filter(Scores!B21:AX21,Scores!B21:AX21>0))"),66.0) -> 66 | C18: 2434 | D18: {=if(B18,if(countif(Scores!B21:AX21,B18)=1,concat("💎",XLOOKUP(B18,Scores!B21:AX21,Scores!B$1:AX$1)),concat("🥇 x",countif(Scores!B21:AX21,B18))),"")} -> 💎Code Golf International | E18: =if(countif(Scores!B21:AX21,B18)=1,F18,-1) -> 66 | F18: =if(B18,B18,-1) -> 66 | G18: =IFERROR(__xludf.DUMMYFUNCTION("if(iferror(small(filter(Scores!B21:AX21,Scores!B21:AX21>0),2),-1)<>F18,iferror(small(filter(Scores!B21:AX21,Scores!B21:AX21>0),2),-1),-1)"),67.0) -> 67 | H18: =IFERROR(__xludf.DUMMYFUNCTION("if(iferror(small(filter(Scores!B21:AX21,Scores!B21:AX21>0),3),-1)<>iferror(small(filter(Scores!B21:AX21,Scores!B21:AX21>0),2),-1),iferror(small(filter(Scores!B21:AX21,Scores!B21:AX21>0),3),-1),-1)"),-1.0) -> -1 | I18: =IFERROR(__xludf.DUMMYFUNCTION("IFERROR(COLUMNS(filter(Scores!B21:AE21,Scores!B21:AE21)),"""")"),45.0) -> 45 | J18: =COUNTIF(Scores!B21:AX21,B18) -> 1 | K18: =IFERROR(__xludf.DUMMYFUNCTION("""COMPUTED_VALUE"""),10.0) -> 10 | N18: =N17+10 -> 90 | O18: =CONCATENATE(N18,IF(N19<1000,concat("-",N19-1),"+")) -> 90-99 | P18: =countif($B$9:$B$408,concat(">=",N18))-countif($B$9:$B$408,concat(">=",N19)) -> 39 | S18: 249 | T18: 26 | U18: 2474 | W18: 209 | X18: 247 | Y18: 2253 | AA18: 89 | AB18: 34 | AC18: 232
A19: =HYPERLINK("https://arcprize.org/play?task=09629e4f", 11) -> 11 | B19: =IFERROR(__xludf.DUMMYFUNCTION("min(filter(Scores!B22:AX22,Scores!B22:AX22>0))"),114.0) -> 114 | C19: 2386 | D19: {=if(B19,if(countif(Scores!B22:AX22,B19)=1,concat("💎",XLOOKUP(B19,Scores!B22:AX22,Scores!B$1:AX$1)),concat("🥇 x",countif(Scores!B22:AX22,B19))),"")} -> 💎ox jam | E19: =if(countif(Scores!B22:AX22,B19)=1,F19,-1) -> 114 | F19: =if(B19,B19,-1) -> 114 | G19: =IFERROR(__xludf.DUMMYFUNCTION("if(iferror(small(filter(Scores!B22:AX22,Scores!B22:AX22>0),2),-1)<>F19,iferror(small(filter(Scores!B22:AX22,Scores!B22:AX22>0),2),-1),-1)"),120.0) -> 120 | H19: =IFERROR(__xludf.DUMMYFUNCTION("if(iferror(small(filter(Scores!B22:AX22,Scores!B22:AX22>0),3),-1)<>iferror(small(filter(Scores!B22:AX22,Scores!B22:AX22>0),2),-1),iferror(small(filter(Scores!B22:AX22,Scores!B22:AX22>0),3),-1),-1)"),121.0) -> 121 | I19: =IFERROR(__xludf.DUMMYFUNCTION("IFERROR(COLUMNS(filter(Scores!B22:AE22,Scores!B22:AE22)),"""")"),42.0) -> 42 | J19: =COUNTIF(Scores!B22:AX22,B19) -> 1 | K19: =IFERROR(__xludf.DUMMYFUNCTION("""COMPUTED_VALUE"""),11.0) -> 11 | N19: =N18+10 -> 100 | O19: =CONCATENATE(N19,IF(N20<1000,concat("-",N20-1),"+")) -> 100-109 | P19: =countif($B$9:$B$408,concat(">=",N19))-countif($B$9:$B$408,concat(">=",N20)) -> 30 | S19: 380 | T19: 27 | U19: 2473 | W19: 219 | X19: 241 | Y19: 2259 | AA19: 80 | AB19: 34 | AC19: 231
A20: =HYPERLINK("https://arcprize.org/play?task=0962bcdd", 12) -> 12 | B20: =IFERROR(__xludf.DUMMYFUNCTION("min(filter(Scores!B23:AX23,Scores!B23:AX23>0))"),122.0) -> 122 | C20: 2378 | D20: {=if(B20,if(countif(Scores!B23:AX23,B20)=1,concat("💎",XLOOKUP(B20,Scores!B23:AX23,Scores!B$1:AX$1)),concat("🥇 x",countif(Scores!B23:AX23,B20))),"")} -> 💎Code Golf International | E20: =if(countif(Scores!B23:AX23,B20)=1,F20,-1) -> 122 | F20: =if(B20,B20,-1) -> 122 | G20: =IFERROR(__xludf.DUMMYFUNCTION("if(iferror(small(filter(Scores!B23:AX23,Scores!B23:AX23>0),2),-1)<>F20,iferror(small(filter(Scores!B23:AX23,Scores!B23:AX23>0),2),-1),-1)"),126.0) -> 126 | H20: =IFERROR(__xludf.DUMMYFUNCTION("if(iferror(small(filter(Scores!B23:AX23,Scores!B23:AX23>0),3),-1)<>iferror(small(filter(Scores!B23:AX23,Scores!B23:AX23>0),2),-1),iferror(small(filter(Scores!B23:AX23,Scores!B23:AX23>0),3),-1),-1)"),129.0) -> 129 | I20: =IFERROR(__xludf.DUMMYFUNCTION("IFERROR(COLUMNS(filter(Scores!B23:AE23,Scores!B23:AE23)),"""")"),40.0) -> 40 | J20: =COUNTIF(Scores!B23:AX23,B20) -> 1 | K20: =IFERROR(__xludf.DUMMYFUNCTION("""COMPUTED_VALUE"""),12.0) -> 12 | N20: =N19+10 -> 110 | O20: =CONCATENATE(N20,IF(N21<1000,concat("-",N21-1),"+")) -> 110-119 | P20: =countif($B$9:$B$408,concat(">=",N20))-countif($B$9:$B$408,concat(">=",N21)) -> 22 | S20: 103 | T20: 29 | U20: 2471 | W20: 66 | X20: 237 | Y20: 2263 | AA20: 191 | AB20: 34 | AC20: 221
A21: =HYPERLINK("https://arcprize.org/play?task=0a938d79", 13) -> 13 | B21: =IFERROR(__xludf.DUMMYFUNCTION("min(filter(Scores!B24:AX24,Scores!B24:AX24>0))"),124.0) -> 124 | C21: 2376 | D21: {=if(B21,if(countif(Scores!B24:AX24,B21)=1,concat("💎",XLOOKUP(B21,Scores!B24:AX24,Scores!B$1:AX$1)),concat("🥇 x",countif(Scores!B24:AX24,B21))),"")} -> 💎Code Golf International | E21: =if(countif(Scores!B24:AX24,B21)=1,F21,-1) -> 124 | F21: =if(B21,B21,-1) -> 124 | G21: =IFERROR(__xludf.DUMMYFUNCTION("if(iferror(small(filter(Scores!B24:AX24,Scores!B24:AX24>0),2),-1)<>F21,iferror(small(filter(Scores!B24:AX24,Scores!B24:AX24>0),2),-1),-1)"),129.0) -> 129 | H21: =IFERROR(__xludf.DUMMYFUNCTION("if(iferror(small(filter(Scores!B24:AX24,Scores!B24:AX24>0),3),-1)<>iferror(small(filter(Scores!B24:AX24,Scores!B24:AX24>0),2),-1),iferror(small(filter(Scores!B24:AX24,Scores!B24:AX24>0),3),-1),-1)"),136.0) -> 136 | I21: =IFERROR(__xludf.DUMMYFUNCTION("IFERROR(COLUMNS(filter(Scores!B24:AE24,Scores!B24:AE24)),"""")"),41.0) -> 41 | J21: =COUNTIF(Scores!B24:AX24,B21) -> 1 | K21: =IFERROR(__xludf.DUMMYFUNCTION("""COMPUTED_VALUE"""),13.0) -> 13 | N21: =N20+10 -> 120 | O21: =CONCATENATE(N21,IF(N22<1000,concat("-",N22-1),"+")) -> 120-129 | P21: =countif($B$9:$B$408,concat(">=",N21))-countif($B$9:$B$408,concat(">=",N22)) -> 15 | S21: 150 | T21: 30 | U21: 2470 | W21: 157 | X21: 237 | Y21: 2263 | AA21: 324 | AB21: 34 | AC21: 216
A22: =HYPERLINK("https://arcprize.org/play?task=0b148d64", 14) -> 14 | B22: =IFERROR(__xludf.DUMMYFUNCTION("min(filter(Scores!B25:AX25,Scores!B25:AX25>0))"),57.0) -> 57 | C22: 2443 | D22: {=if(B22,if(countif(Scores!B25:AX25,B22)=1,concat("💎",XLOOKUP(B22,Scores!B25:AX25,Scores!B$1:AX$1)),concat("🥇 x",countif(Scores!B25:AX25,B22))),"")} -> 💎Code Golf International | E22: =if(countif(Scores!B25:AX25,B22)=1,F22,-1) -> 57 | F22: =if(B22,B22,-1) -> 57 | G22: =IFERROR(__xludf.DUMMYFUNCTION("if(iferror(small(filter(Scores!B25:AX25,Scores!B25:AX25>0),2),-1)<>F22,iferror(small(filter(Scores!B25:AX25,Scores!B25:AX25>0),2),-1),-1)"),67.0) -> 67 | H22: =IFERROR(__xludf.DUMMYFUNCTION("if(iferror(small(filter(Scores!B25:AX25,Scores!B25:AX25>0),3),-1)<>iferror(small(filter(Scores!B25:AX25,Scores!B25:AX25>0),2),-1),iferror(small(filter(Scores!B25:AX25,Scores!B25:AX25>0),3),-1),-1)"),68.0) -> 68 | I22: =IFERROR(__xludf.DUMMYFUNCTION("IFERROR(COLUMNS(filter(Scores!B25:AE25,Scores!B25:AE25)),"""")"),44.0) -> 44 | J22: =COUNTIF(Scores!B25:AX25,B22) -> 1 | K22: =IFERROR(__xludf.DUMMYFUNCTION("""COMPUTED_VALUE"""),14.0) -> 14 | N22: =N21+10 -> 130 | O22: =CONCATENATE(N22,IF(N23<1000,concat("-",N23-1),"+")) -> 130-139 | P22: =countif($B$9:$B$408,concat(">=",N22))-countif($B$9:$B$408,concat(">=",N23)) -> 13 | S22: 326 | T22: 30 | U22: 2470 | W22: 89 | X22: 232 | Y22: 2268 | AA22: 238 | AB22: 34 | AC22: 195
A23: =HYPERLINK("https://arcprize.org/play?task=0ca9ddb6", 15) -> 15 | B23: =IFERROR(__xludf.DUMMYFUNCTION("min(filter(Scores!B26:AX26,Scores!B26:AX26>0))"),87.0) -> 87 | C23: 2413 | D23: {=if(B23,if(countif(Scores!B26:AX26,B23)=1,concat("💎",XLOOKUP(B23,Scores!B26:AX26,Scores!B$1:AX$1)),concat("🥇 x",countif(Scores!B26:AX26,B23))),"")} -> 💎jailctf merger | E23: =if(countif(Scores!B26:AX26,B23)=1,F23,-1) -> 87 | F23: =if(B23,B23,-1) -> 87 | G23: =IFERROR(__xludf.DUMMYFUNCTION("if(iferror(small(filter(Scores!B26:AX26,Scores!B26:AX26>0),2),-1)<>F23,iferror(small(filter(Scores!B26:AX26,Scores!B26:AX26>0),2),-1),-1)"),92.0) -> 92 | H23: =IFERROR(__xludf.DUMMYFUNCTION("if(iferror(small(filter(Scores!B26:AX26,Scores!B26:AX26>0),3),-1)<>iferror(small(filter(Scores!B26:AX26,Scores!B26:AX26>0),2),-1),iferror(small(filter(Scores!B26:AX26,Scores!B26:AX26>0),3),-1),-1)"),-1.0) -> -1 | I23: =IFERROR(__xludf.DUMMYFUNCTION("IFERROR(COLUMNS(filter(Scores!B26:AE26,Scores!B26:AE26)),"""")"),41.0) -> 41 | J23: =COUNTIF(Scores!B26:AX26,B23) -> 1 | K23: =IFERROR(__xludf.DUMMYFUNCTION("""COMPUTED_VALUE"""),15.0) -> 15 | N23: =N22+10 -> 140 | O23: =CONCATENATE(N23,IF(N24<1000,concat("-",N24-1),"+")) -> 140-149 | P23: =countif($B$9:$B$408,concat(">=",N23))-countif($B$9:$B$408,concat(">=",N24)) -> 4 | S23: 376 | T23: 30 | U23: 2470 | W23: 80 | X23: 231 | Y23: 2269 | AA23: 319 | AB23: 34 | AC23: 194
A24: =HYPERLINK("https://arcprize.org/play?task=0d3d703e", 16) -> 16 | B24: =IFERROR(__xludf.DUMMYFUNCTION("min(filter(Scores!B27:AX27,Scores!B27:AX27>0))"),43.0) -> 43 | C24: 2457 | D24: {=if(B24,if(countif(Scores!B27:AX27,B24)=1,concat("💎",XLOOKUP(B24,Scores!B27:AX27,Scores!B$1:AX$1)),concat("🥇 x",countif(Scores!B27:AX27,B24))),"")} -> 🥇 x5 | E24: =if(countif(Scores!B27:AX27,B24)=1,F24,-1) -> -1 | F24: =if(B24,B24,-1) -> 43 | G24: =IFERROR(__xludf.DUMMYFUNCTION("if(iferror(small(filter(Scores!B27:AX27,Scores!B27:AX27>0),2),-1)<>F24,iferror(small(filter(Scores!B27:AX27,Scores!B27:AX27>0),2),-1),-1)"),-1.0) -> -1 | H24: =IFERROR(__xludf.DUMMYFUNCTION("if(iferror(small(filter(Scores!B27:AX27,Scores!B27:AX27>0),3),-1)<>iferror(small(filter(Scores!B27:AX27,Scores!B27:AX27>0),2),-1),iferror(small(filter(Scores!B27:AX27,Scores!B27:AX27>0),3),-1),-1)"),-1.0) -> -1 | I24: =IFERROR(__xludf.DUMMYFUNCTION("IFERROR(COLUMNS(filter(Scores!B27:AE27,Scores!B27:AE27)),"""")"),47.0) -> 47 | J24: =COUNTIF(Scores!B27:AX27,B24) -> 5 | K24: =IFERROR(__xludf.DUMMYFUNCTION("""COMPUTED_VALUE"""),16.0) -> 16 | N24: =N23+10 -> 150 | O24: =CONCATENATE(N24,IF(N25<1000,concat("-",N25-1),"+")) -> 150-159 | P24: =countif($B$9:$B$408,concat(">=",N24))-countif($B$9:$B$408,concat(">=",N25)) -> 6 | S24: 301 | T24: 31 | U24: 2469 | W24: 285 | X24: 226 | Y24: 2274 | AA24: 268 | AB24: 34 | AC24: 190
